<?xml version="1.0" ?>
<robot name="gimbal_small_2d">
  <joint name="gimbal_small_2d__tilt_joint" type="revolute">
    <parent link="gimbal_small_2d__base_link"/>
    <child link="gimbal_small_2d__tilt_link"/>
    <origin xyz="0  0  0.2" rpy="0 0 0"/>
    <axis xyz="1 0 0"/>
    <limit lower="-0.1" upper="3.14159265" effort="10.0" velocity="-1.0"/>
  </joint>
  <link name="gimbal_small_2d__base_link">
    <inertial>
      <mass value="0.2"/>
      <origin xyz="0 0 0" rpy="0 0 0"/>
      <inertia ixx="0.0001" ixy="0" ixz="0" iyy="0.0001" iyz="0" izz="0.0001"/>
    </inertial>
    <collision name="gimbal_small_2d__base_col">
      <origin xyz="0.01  0.075 0.155" rpy="0 0 0"/>
      <geometry>
        <box size="0.1 0.05 0.15"/>
      </geometry>
    </collision>
    <visual name="gimbal_small_2d__base_main_viz">
      <origin xyz="0   0   0.18" rpy="0 0 0"/>
      <geometry>
        <mesh filename="$(find iq_sim)/models/gimbal_small_2d/meshes/base_main.dae" scale="0.001 0.001 0.001"/>
      </geometry>
    </visual>
    <visual name="gimbal_small_2d__base_arm_viz">
      <origin xyz="0   0   0.18" rpy="0 0 0"/>
      <geometry>
        <mesh filename="$(find iq_sim)/models/gimbal_small_2d/meshes/base_arm.dae" scale="0.001 0.001 0.001"/>
      </geometry>
    </visual>
  </link>
  <link name="gimbal_small_2d__tilt_link">
    <inertial>
      <mass value="0.01"/>
      <origin xyz="0 0 0" rpy="0 0 0"/>
      <inertia ixx="0.00001" ixy="0" ixz="0" iyy="0.00001" iyz="0" izz="0.00001"/>
    </inertial>
    <collision name="gimbal_small_2d__tilt_col">
      <origin xyz="0     0    -0.025" rpy="0 0 0"/>
      <geometry>
        <mesh filename="$(find iq_sim)/models/gimbal_small_2d/meshes/tilt.dae" scale="0.001 0.001 0.001"/>
      </geometry>
    </collision>
    <collision name="gimbal_small_2d__camera_col">
      <origin xyz="0 0 0" rpy="0 0 0"/>
      <geometry>
        <cylinder radius="0.025" length="0.050"/>
      </geometry>
    </collision>
    <visual name="gimbal_small_2d__tilt_viz">
      <origin xyz="0     0    -0.025" rpy="0 0 0"/>
      <geometry>
        <mesh filename="$(find iq_sim)/models/gimbal_small_2d/meshes/tilt.dae" scale="0.001 0.001 0.001"/>
      </geometry>
    </visual>
    <visual name="gimbal_small_2d__camera_viz">
      <origin xyz="0 0 0" rpy="0 0 0"/>
      <geometry>
        <cylinder radius="0.025" length="0.050"/>
      </geometry>
    </visual>
  </link>
</robot>
