<?xml version="1.0" ?>
<robot name="iris">
  <link name="dummy_link"/>
  <joint name="base_link_joint" type="fixed">
  <origin rpy="0 0 0" xyz="0 0 0"/>
  <parent link="dummy_link"/>
  <child link="iris__base_link"/>
  </joint>
  <joint name="iris__iris/ground_truth/odometry_sensorgt_joint" type="fixed">
    <parent link="iris__base_link"/>
    <child link="iris__iris/ground_truth/odometry_sensorgt_link"/>
    <origin xyz="0      0      0.19492" rpy="0 0 0"/>
    <axis xyz="0 0 1"/>
    <limit lower="0.0" upper="0.0" effort="0.0" velocity="0.0"/>
  </joint>
  <joint name="iris__iris/imu_joint" type="fixed">
    <parent link="iris__base_link"/>
    <child link="iris__iris/imu_link"/>
    <origin xyz="0      0      0.19492" rpy="0 0 0"/>
    <axis xyz="0 0 1"/>
    <limit lower="0.0" upper="0.0" effort="0.0" velocity="0.0"/>
  </joint>
  <joint name="iris__rotor_0_joint" type="revolute">
    <parent link="iris__base_link"/>
    <child link="iris__rotor_0"/>
    <origin xyz="0.13    -0.22     0.21792" rpy="0 0 0"/>
    <axis xyz="0 0 1"/>
    <limit lower="-1e+16" upper="1e+16" effort="0.0" velocity="0.0"/>
  </joint>
  <joint name="iris__rotor_1_joint" type="revolute">
    <parent link="iris__base_link"/>
    <child link="iris__rotor_1"/>
    <origin xyz="-0.13     0.2      0.21792" rpy="0 0 0"/>
    <axis xyz="0 0 1"/>
    <limit lower="-1e+16" upper="1e+16" effort="0.0" velocity="0.0"/>
  </joint>
  <joint name="iris__rotor_2_joint" type="revolute">
    <parent link="iris__base_link"/>
    <child link="iris__rotor_2"/>
    <origin xyz="0.13    0.22    0.21792" rpy="0 0 0"/>
    <axis xyz="0 0 1"/>
    <limit lower="-1e+16" upper="1e+16" effort="0.0" velocity="0.0"/>
  </joint>
  <joint name="iris__rotor_3_joint" type="revolute">
    <parent link="iris__base_link"/>
    <child link="iris__rotor_3"/>
    <origin xyz="-0.13    -0.2      0.21792" rpy="0 0 0"/>
    <axis xyz="0 0 1"/>
    <limit lower="-1e+16" upper="1e+16" effort="0.0" velocity="0.0"/>
  </joint>
  <link name="iris__base_link">
    <inertial>
      <mass value="1.5"/>
      <origin xyz="0 0 0" rpy="0 0 0"/>
      <inertia ixx="0.008" ixy="0" ixz="0" iyy="0.015" iyz="0" izz="0.017"/>
    </inertial>
    <collision name="iris__base_link_collision">
      <origin xyz="0      0      0.11492" rpy="0 0 0"/>
      <geometry>
        <box size="0.47 0.47 0.23"/>
      </geometry>
    </collision>
    <visual name="iris__base_link_visual">
      <origin xyz="0      0      0.19492" rpy="0 0 0"/>
      <geometry>
        <mesh filename="$(find iq_sim)/models/iris_with_standoffs/meshes/iris.dae" scale="1.0 1.0 1.0"/>
      </geometry>
    </visual>
    <visual name="iris__front_left_leg_visual">
      <origin xyz="0.123   0.22    0.08492" rpy="0 0 0"/>
      <geometry>
        <cylinder radius="0.005" length="0.17"/>
      </geometry>
    </visual>
    <visual name="iris__front_right_leg_visual">
      <origin xyz="0.123   -0.22     0.08492" rpy="0 0 0"/>
      <geometry>
        <cylinder radius="0.005" length="0.17"/>
      </geometry>
    </visual>
    <visual name="iris__rear_left_leg_visual">
      <origin xyz="-0.14     0.21     0.08492" rpy="0 0 0"/>
      <geometry>
        <cylinder radius="0.005" length="0.17"/>
      </geometry>
    </visual>
    <visual name="iris__rear_right_leg_visual">
      <origin xyz="-0.14    -0.21     0.08492" rpy="0 0 0"/>
      <geometry>
        <cylinder radius="0.005" length="0.17"/>
      </geometry>
    </visual>
  </link>
  <link name="iris__iris/ground_truth/odometry_sensorgt_link">
    <inertial>
      <mass value="0.15"/>
      <origin xyz="0 0 0" rpy="0 0 0"/>
      <inertia ixx="0.0001" ixy="0" ixz="0" iyy="0.0002" iyz="0" izz="0.0002"/>
    </inertial>
  </link>
  <link name="iris__iris/imu_link">
    <inertial>
      <mass value="0.15"/>
      <origin xyz="0 0 0" rpy="0 0 0"/>
      <inertia ixx="0.00001" ixy="0" ixz="0" iyy="0.00002" iyz="0" izz="0.00002"/>
    </inertial>
  </link>
  <link name="iris__rotor_0">
    <inertial>
      <mass value="0.025"/>
      <origin xyz="0 0 0" rpy="0 0 0"/>
      <inertia ixx="9.75e-06" ixy="0" ixz="0" iyy="0.000166704" iyz="0" izz="0.000167604"/>
    </inertial>
    <collision name="iris__rotor_0_collision">
      <origin xyz="0 0 0" rpy="0 0 0"/>
      <geometry>
        <cylinder radius="0.1" length="0.005"/>
      </geometry>
    </collision>
    <visual name="iris__rotor_0_visual">
      <origin xyz="0 0 0" rpy="0 0 0"/>
      <geometry>
        <mesh filename="$(find iq_sim)/models/iris_with_standoffs/meshes/iris_prop_ccw.dae" scale="1 1 1"/>
      </geometry>
    </visual>
  </link>
  <link name="iris__rotor_1">
    <inertial>
      <mass value="0.025"/>
      <origin xyz="0 0 0" rpy="0 0 0"/>
      <inertia ixx="9.75e-06" ixy="0" ixz="0" iyy="0.000166704" iyz="0" izz="0.000167604"/>
    </inertial>
    <collision name="iris__rotor_1_collision">
      <origin xyz="0 0 0" rpy="0 0 0"/>
      <geometry>
        <cylinder radius="0.1" length="0.005"/>
      </geometry>
    </collision>
    <visual name="iris__rotor_1_visual">
      <origin xyz="0 0 0" rpy="0 0 0"/>
      <geometry>
        <mesh filename="$(find iq_sim)/models/iris_with_standoffs/meshes/iris_prop_ccw.dae" scale="1 1 1"/>
      </geometry>
    </visual>
  </link>
  <link name="iris__rotor_2">
    <inertial>
      <mass value="0.025"/>
      <origin xyz="0 0 0" rpy="0 0 0"/>
      <inertia ixx="9.75e-06" ixy="0" ixz="0" iyy="0.000166704" iyz="0" izz="0.000167604"/>
    </inertial>
    <collision name="iris__rotor_2_collision">
      <origin xyz="0 0 0" rpy="0 0 0"/>
      <geometry>
        <cylinder radius="0.1" length="0.005"/>
      </geometry>
    </collision>
    <visual name="iris__rotor_2_visual">
      <origin xyz="0 0 0" rpy="0 0 0"/>
      <geometry>
        <mesh filename="$(find iq_sim)/models/iris_with_standoffs/meshes/iris_prop_cw.dae" scale="1 1 1"/>
      </geometry>
    </visual>
  </link>
  <link name="iris__rotor_3">
    <inertial>
      <mass value="0.025"/>
      <origin xyz="0 0 0" rpy="0 0 0"/>
      <inertia ixx="9.75e-06" ixy="0" ixz="0" iyy="0.000166704" iyz="0" izz="0.000167604"/>
    </inertial>
    <collision name="iris__rotor_3_collision">
      <origin xyz="0 0 0" rpy="0 0 0"/>
      <geometry>
        <cylinder radius="0.1" length="0.005"/>
      </geometry>
    </collision>
    <visual name="iris__rotor_3_visual">
      <origin xyz="0 0 0" rpy="0 0 0"/>
      <geometry>
        <mesh filename="$(find iq_sim)/models/iris_with_standoffs/meshes/iris_prop_cw.dae" scale="1 1 1"/>
      </geometry>
    </visual>
  </link>
</robot>
