<?xml version="1.0" ?>
<robot name="iris_demo">
  <link name="dummy_link"/>
  <joint name="base_link_joint" type="fixed">
    <origin rpy="0 0 0" xyz="0 0 0"/>
    <parent link="dummy_link"/>
    <child link="iris_demo__iris__base_link"/>
  </joint>
  <joint name="iris_demo__iris_gimbal_mount" type="fixed">
    <parent link="iris_demo__iris__base_link"/>
    <child link="iris_demo__gimbal_small_2d__base_link"/>
    <origin xyz="0 -0.01014  0.07014" rpy="1.57 0   1.57"/>
    <axis xyz="0.0e+00 1.0e+00 7.9e-04"/>
    <limit lower="0.0" upper="0.0" effort="0.0" velocity="0.0"/>
  </joint>
  <joint name="iris_demo__iris__iris/ground_truth/odometry_sensorgt_joint" type="fixed">
    <parent link="iris_demo__iris__base_link"/>
    <child link="iris_demo__iris__iris/ground_truth/odometry_sensorgt_link"/>
    <origin xyz="0      0      0.19492" rpy="0 0 0"/>
    <axis xyz="0 0 1"/>
    <limit lower="0.0" upper="0.0" effort="0.0" velocity="0.0"/>
  </joint>
  <joint name="iris_demo__iris__iris/imu_joint" type="fixed">
    <parent link="iris_demo__iris__base_link"/>
    <child link="iris_demo__iris__iris/imu_link"/>
    <origin xyz="0      0      0.19492" rpy="0 0 0"/>
    <axis xyz="0 0 1"/>
    <limit lower="0.0" upper="0.0" effort="0.0" velocity="0.0"/>
  </joint>
  <joint name="iris_demo__iris__rotor_0_joint" type="revolute">
    <parent link="iris_demo__iris__base_link"/>
    <child link="iris_demo__iris__rotor_0"/>
    <origin xyz="0.13    -0.22     0.21792" rpy="0 0 0"/>
    <axis xyz="0 0 1"/>
    <limit lower="-1e+16" upper="1e+16" effort="0.0" velocity="0.0"/>
  </joint>
  <joint name="iris_demo__iris__rotor_1_joint" type="revolute">
    <parent link="iris_demo__iris__base_link"/>
    <child link="iris_demo__iris__rotor_1"/>
    <origin xyz="-0.13     0.2      0.21792" rpy="0 0 0"/>
    <axis xyz="0 0 1"/>
    <limit lower="-1e+16" upper="1e+16" effort="0.0" velocity="0.0"/>
  </joint>
  <joint name="iris_demo__iris__rotor_2_joint" type="revolute">
    <parent link="iris_demo__iris__base_link"/>
    <child link="iris_demo__iris__rotor_2"/>
    <origin xyz="0.13    0.22    0.21792" rpy="0 0 0"/>
    <axis xyz="0 0 1"/>
    <limit lower="-1e+16" upper="1e+16" effort="0.0" velocity="0.0"/>
  </joint>
  <joint name="iris_demo__iris__rotor_3_joint" type="revolute">
    <parent link="iris_demo__iris__base_link"/>
    <child link="iris_demo__iris__rotor_3"/>
    <origin xyz="-0.13    -0.2      0.21792" rpy="0 0 0"/>
    <axis xyz="0 0 1"/>
    <limit lower="-1e+16" upper="1e+16" effort="0.0" velocity="0.0"/>
  </joint>
  <link name="iris_demo__iris__base_link">
    <inertial>
      <mass value="1.5"/>
      <origin xyz="0 0 0" rpy="0 0 0"/>
      <inertia ixx="0.008" ixy="0" ixz="0" iyy="0.015" iyz="0" izz="0.017"/>
    </inertial>
    <collision name="iris_demo__iris__base_link_collision">
      <origin xyz="0      0      0.11492" rpy="0 0 0"/>
      <geometry>
        <box size="0.47 0.47 0.23"/>
      </geometry>
    </collision>
    <visual name="iris_demo__iris__base_link_visual">
      <origin xyz="0      0      0.19492" rpy="0 0 0"/>
      <geometry>
        <mesh filename="$(find iq_sim)/models/iris_with_standoffs/meshes/iris.dae" scale="1.0 1.0 1.0"/>
      </geometry>
    </visual>
    <visual name="iris_demo__iris__front_left_leg_visual">
      <origin xyz="0.123   0.22    0.08492" rpy="0 0 0"/>
      <geometry>
        <cylinder radius="0.005" length="0.17"/>
      </geometry>
    </visual>
    <visual name="iris_demo__iris__front_right_leg_visual">
      <origin xyz="0.123   -0.22     0.08492" rpy="0 0 0"/>
      <geometry>
        <cylinder radius="0.005" length="0.17"/>
      </geometry>
    </visual>
    <visual name="iris_demo__iris__rear_left_leg_visual">
      <origin xyz="-0.14     0.21     0.08492" rpy="0 0 0"/>
      <geometry>
        <cylinder radius="0.005" length="0.17"/>
      </geometry>
    </visual>
    <visual name="iris_demo__iris__rear_right_leg_visual">
      <origin xyz="-0.14    -0.21     0.08492" rpy="0 0 0"/>
      <geometry>
        <cylinder radius="0.005" length="0.17"/>
      </geometry>
    </visual>
  </link>
  <link name="iris_demo__iris__iris/ground_truth/odometry_sensorgt_link">
    <inertial>
      <mass value="0.15"/>
      <origin xyz="0 0 0" rpy="0 0 0"/>
      <inertia ixx="0.0001" ixy="0" ixz="0" iyy="0.0002" iyz="0" izz="0.0002"/>
    </inertial>
  </link>
  <link name="iris_demo__iris__iris/imu_link">
    <inertial>
      <mass value="0.15"/>
      <origin xyz="0 0 0" rpy="0 0 0"/>
      <inertia ixx="0.00001" ixy="0" ixz="0" iyy="0.00002" iyz="0" izz="0.00002"/>
    </inertial>
  </link>
  <link name="iris_demo__iris__rotor_0">
    <inertial>
      <mass value="0.025"/>
      <origin xyz="0 0 0" rpy="0 0 0"/>
      <inertia ixx="9.75e-06" ixy="0" ixz="0" iyy="0.000166704" iyz="0" izz="0.000167604"/>
    </inertial>
    <collision name="iris_demo__iris__rotor_0_collision">
      <origin xyz="0 0 0" rpy="0 0 0"/>
      <geometry>
        <cylinder radius="0.1" length="0.005"/>
      </geometry>
    </collision>
    <visual name="iris_demo__iris__rotor_0_visual">
      <origin xyz="0 0 0" rpy="0 0 0"/>
      <geometry>
        <mesh filename="$(find iq_sim)/models/iris_with_standoffs/meshes/iris_prop_ccw.dae" scale="1 1 1"/>
      </geometry>
    </visual>
  </link>
  <link name="iris_demo__iris__rotor_1">
    <inertial>
      <mass value="0.025"/>
      <origin xyz="0 0 0" rpy="0 0 0"/>
      <inertia ixx="9.75e-06" ixy="0" ixz="0" iyy="0.000166704" iyz="0" izz="0.000167604"/>
    </inertial>
    <collision name="iris_demo__iris__rotor_1_collision">
      <origin xyz="0 0 0" rpy="0 0 0"/>
      <geometry>
        <cylinder radius="0.1" length="0.005"/>
      </geometry>
    </collision>
    <visual name="iris_demo__iris__rotor_1_visual">
      <origin xyz="0 0 0" rpy="0 0 0"/>
      <geometry>
        <mesh filename="$(find iq_sim)/models/iris_with_standoffs/meshes/iris_prop_ccw.dae" scale="1 1 1"/>
      </geometry>
    </visual>
  </link>
  <link name="iris_demo__iris__rotor_2">
    <inertial>
      <mass value="0.025"/>
      <origin xyz="0 0 0" rpy="0 0 0"/>
      <inertia ixx="9.75e-06" ixy="0" ixz="0" iyy="0.000166704" iyz="0" izz="0.000167604"/>
    </inertial>
    <collision name="iris_demo__iris__rotor_2_collision">
      <origin xyz="0 0 0" rpy="0 0 0"/>
      <geometry>
        <cylinder radius="0.1" length="0.005"/>
      </geometry>
    </collision>
    <visual name="iris_demo__iris__rotor_2_visual">
      <origin xyz="0 0 0" rpy="0 0 0"/>
      <geometry>
        <mesh filename="$(find iq_sim)/models/iris_with_standoffs/meshes/iris_prop_ccw.dae" scale="1 1 1"/>
      </geometry>
    </visual>
  </link>
  <link name="iris_demo__iris__rotor_3">
    <inertial>
      <mass value="0.025"/>
      <origin xyz="0 0 0" rpy="0 0 0"/>
      <inertia ixx="9.75e-06" ixy="0" ixz="0" iyy="0.000166704" iyz="0" izz="0.000167604"/>
    </inertial>
    <collision name="iris_demo__iris__rotor_3_collision">
      <origin xyz="0 0 0" rpy="0 0 0"/>
      <geometry>
        <cylinder radius="0.1" length="0.005"/>
      </geometry>
    </collision>
    <visual name="iris_demo__iris__rotor_3_visual">
      <origin xyz="0 0 0" rpy="0 0 0"/>
      <geometry>
        <mesh filename="$(find iq_sim)/models/iris_with_standoffs/meshes/iris_prop_ccw.dae" scale="1 1 1"/>
      </geometry>
    </visual>
  </link>
  <joint name="iris_demo__gimbal_small_2d__tilt_joint" type="revolute">
    <parent link="iris_demo__gimbal_small_2d__base_link"/>
    <child link="iris_demo__gimbal_small_2d__tilt_link"/>
    <origin xyz="0   0   0.02" rpy="0 0 0"/>
    <axis xyz="1 0 0"/>
    <limit lower="-0.1" upper="3.14159265" effort="10.0" velocity="-1.0"/>
  </joint>
  <link name="iris_demo__gimbal_small_2d__tilt_link">
    <inertial>
      <mass value="0.01"/>
      <origin xyz="0 0 0" rpy="0 0 0"/>
      <inertia ixx="0.00001" ixy="0" ixz="0" iyy="0.00001" iyz="0" izz="0.00001"/>
    </inertial>
    <collision name="iris_demo__gimbal_small_2d__tilt_col">
      <origin xyz="0     0    -0.025" rpy="0 0 0"/>
      <geometry>
        <mesh filename="$(find iq_sim)/models/gimbal_small_2d/meshes/tilt.dae" scale="0.001 0.001 0.001"/>
      </geometry>
    </collision>
    <collision name="iris_demo__gimbal_small_2d__camera_col">
      <origin xyz="0 0 0" rpy="0 0 0"/>
      <geometry>
        <cylinder radius="0.025" length="0.050"/>
      </geometry>
    </collision>
    <visual name="iris_demo__gimbal_small_2d__tilt_viz">
      <origin xyz="0     0    -0.025" rpy="0 0 0"/>
      <geometry>
        <mesh filename="$(find iq_sim)/models/gimbal_small_2d/meshes/tilt.dae" scale="0.001 0.001 0.001"/>
      </geometry>
    </visual>
    <visual name="iris_demo__gimbal_small_2d__camera_viz">
      <origin xyz="0 0 0" rpy="0 0 0"/>
      <geometry>
        <cylinder radius="0.025" length="0.050"/>
      </geometry>
    </visual>
  </link>
  <link name="iris_demo__gimbal_small_2d__base_link">
    <inertial>
      <mass value="0.2"/>
      <origin xyz="0 0 0" rpy="0 0 0"/>
      <inertia ixx="0.0001" ixy="0" ixz="0" iyy="0.0001" iyz="0" izz="0.0001"/>
    </inertial>
    <collision name="iris_demo__gimbal_small_2d__base_col">
      <origin xyz="0.01   0.075 -0.025" rpy="0 0 0"/>
      <geometry>
        <box size="0.1 0.05 0.15"/>
      </geometry>
    </collision>
    <visual name="iris_demo__gimbal_small_2d__base_main_viz">
      <origin xyz="0 0 0" rpy="0 0 0"/>
      <geometry>
        <mesh filename="$(find iq_sim)/models/gimbal_small_2d/meshes/base_main.dae" scale="0.001 0.001 0.001"/>
      </geometry>
    </visual>
    <visual name="iris_demo__gimbal_small_2d__base_arm_viz">
      <origin xyz="0 0 0" rpy="0 0 0"/>
      <geometry>
        <mesh filename="$(find iq_sim)/models/gimbal_small_2d/meshes/base_arm.dae" scale="0.001 0.001 0.001"/>
      </geometry>
    </visual>
  </link>

  <!-- Definition of camera and 2D lidar -->
  <joint name="iris_demo__gimbal_small_2d__base_camera_joint" type="fixed">
    <parent link="iris_demo__gimbal_small_2d__tilt_link"/>
    <child link="iris_demo__gimbal_small_2d__camera"/>
    <origin xyz="0   0  0" rpy="1.57 0   1.57"/>
    <axis xyz="0.0e+00 1.0e+00 7.9e-04"/>
    <limit lower="0.0" upper="0.0" effort="0.0" velocity="0.0"/>
  </joint>
  <joint name="iris_demo__hokuyo_joint" type="fixed">
    <parent link="iris_demo__iris__base_link"/>
    <child link="iris_demo__hokuyo_link"/>
    <origin xyz="0   0   0.25" rpy="0 0 0"/>
    <axis xyz="0 0 0"/>
    <limit lower="0" upper="0" effort="0" velocity="0"/>
  </joint>

  <link name="iris_demo__gimbal_small_2d__camera">
    <inertial>
      <mass value="0.1"/>
      <origin xyz="0 0 0" rpy="0 0 0"/>
      <inertia ixx="0.001" ixy="0" ixz="0" iyy="0.001" iyz="0" izz="0.001"/>
    </inertial>
    <visual name="camera_visual">
      <origin xyz="0 0 0" rpy="0 0 0"/>
      <geometry>
        <cylinder radius="0.025" length="0.025"/>
      </geometry>
    </visual>
  </link>
  <link name="iris_demo__hokuyo_link">
    <inertial>
      <mass value="0.016"/>
      <origin xyz="0 0 0" rpy="0 0 0"/>
      <inertia ixx="0.0001" ixy="0" ixz="0" iyy="0.0001" iyz="0" izz="0.0001"/>
    </inertial>
    <collision name="hokuyo_collision">
      <origin xyz="0  0  0.3" rpy="0 0 0"/>
      <geometry>
        <box size="0.1 0.1 0.1"/>
      </geometry>
    </collision>
    <visual name="hokuyo_visual">
      <origin xyz="0   0   0" rpy="0 0 0"/>
      <geometry>
        <mesh filename="$(find iq_sim)/models/hokuyo/meshes/hokuyo.dae" scale="1.0 1.0 1.0"/>
      </geometry>
    </visual>
  </link>


<!-- ******************************************************************* -->
  <gazebo reference="dummy_link">
    <!-- Gimbal small 2d plugin -->
    <plugin name="gimbal_small_2d" filename="libGimbalSmall2dPlugin.so">
      <joint>iris_demo__gimbal_small_2d__tilt_joint</joint>
    </plugin>
  </gazebo>

  <gazebo reference="iris_demo__iris__base_link">
    <!-- Iris with standoffs demo plugins -->
    <plugin name="rotor_0_blade_1" filename="libLiftDragPlugin.so">
      <a0>0.1</a0>
      <alpha_stall>1.4</alpha_stall>
      <cla>0.2500</cla>
      <cda>0.10</cda>
      <cma>0.00</cma>
      <cla_stall>-0.025</cla_stall>
      <cda_stall>0.0</cda_stall>
      <cma_stall>0.0</cma_stall>
      <area>0.2</area>
      <air_density>1.2041</air_density>
      <cp>0.084 0 0</cp>
      <forward>0 1 0</forward>
      <upward>0 0 1</upward>
      <link_name>iris_demo__iris__rotor_0</link_name>
    </plugin>
    <plugin name="rotor_0_blade_2" filename="libLiftDragPlugin.so">
      <a0>0.1</a0>
      <alpha_stall>1.4</alpha_stall>
      <cla>0.2500</cla>
      <cda>0.10</cda>
      <cma>0.00</cma>
      <cla_stall>-0.025</cla_stall>
      <cda_stall>0.0</cda_stall>
      <cma_stall>0.0</cma_stall>
      <area>0.2</area>
      <air_density>1.2041</air_density>
      <cp>-0.084 0 0</cp>
      <forward>0 -1 0</forward>
      <upward>0 0 1</upward>
      <link_name>iris_demo__iris__rotor_0</link_name>
    </plugin>

    <plugin name="rotor_1_blade_1" filename="libLiftDragPlugin.so">
      <a0>0.1</a0>
      <alpha_stall>1.4</alpha_stall>
      <cla>0.2500</cla>
      <cda>0.10</cda>
      <cma>0.00</cma>
      <cla_stall>-0.025</cla_stall>
      <cda_stall>0.0</cda_stall>
      <cma_stall>0.0</cma_stall>
      <area>0.2</area>
      <air_density>1.2041</air_density>
      <cp>0.084 0 0</cp>
      <forward>0 1 0</forward>
      <upward>0 0 1</upward>
      <link_name>iris_demo__iris__rotor_1</link_name>
    </plugin>
    <plugin name="rotor_1_blade_2" filename="libLiftDragPlugin.so">
      <a0>0.1</a0>
      <alpha_stall>1.4</alpha_stall>
      <cla>0.2500</cla>
      <cda>0.10</cda>
      <cma>0.00</cma>
      <cla_stall>-0.025</cla_stall>
      <cda_stall>0.0</cda_stall>
      <cma_stall>0.0</cma_stall>
      <area>0.2</area>
      <air_density>1.2041</air_density>
      <cp>-0.084 0 0</cp>
      <forward>0 -1 0</forward>
      <upward>0 0 1</upward>
      <link_name>iris_demo__iris__rotor_1</link_name>
    </plugin>

    <plugin name="rotor_2_blade_1" filename="libLiftDragPlugin.so">
      <a0>0.1</a0>
      <alpha_stall>1.4</alpha_stall>
      <cla>0.2500</cla>
      <cda>0.10</cda>
      <cma>0.00</cma>
      <cla_stall>-0.025</cla_stall>
      <cda_stall>0.0</cda_stall>
      <cma_stall>0.0</cma_stall>
      <area>0.2</area>
      <air_density>1.2041</air_density>
      <cp>0.084 0 0</cp>
      <forward>0 -1 0</forward>
      <upward>0 0 1</upward>
      <link_name>iris_demo__iris__rotor_2</link_name>
    </plugin>
    <plugin name="rotor_2_blade_2" filename="libLiftDragPlugin.so">
      <a0>0.1</a0>
      <alpha_stall>1.4</alpha_stall>
      <cla>0.2500</cla>
      <cda>0.10</cda>
      <cma>0.00</cma>
      <cla_stall>-0.025</cla_stall>
      <cda_stall>0.0</cda_stall>
      <cma_stall>0.0</cma_stall>
      <area>0.2</area>
      <air_density>1.2041</air_density>
      <cp>-0.084 0 0</cp>
      <forward>0 1 0</forward>
      <upward>0 0 1</upward>
      <link_name>iris_demo__iris__rotor_2</link_name>
    </plugin>

    <plugin name="rotor_3_blade_1" filename="libLiftDragPlugin.so">
      <a0>0.1</a0>
      <alpha_stall>1.4</alpha_stall>
      <cla>0.2500</cla>
      <cda>0.10</cda>
      <cma>0.00</cma>
      <cla_stall>-0.025</cla_stall>
      <cda_stall>0.0</cda_stall>
      <cma_stall>0.0</cma_stall>
      <area>0.2</area>
      <air_density>1.2041</air_density>
      <cp>0.084 0 0</cp>
      <forward>0 -1 0</forward>
      <upward>0 0 1</upward>
      <link_name>iris_demo__iris__rotor_3</link_name>
    </plugin>
    <plugin name="rotor_3_blade_2" filename="libLiftDragPlugin.so">
      <a0>0.1</a0>
      <alpha_stall>1.4</alpha_stall>
      <cla>0.2500</cla>
      <cda>0.10</cda>
      <cma>0.00</cma>
      <cla_stall>-0.025</cla_stall>
      <cda_stall>0.0</cda_stall>
      <cma_stall>0.0</cma_stall>
      <area>0.2</area>
      <air_density>1.2041</air_density>
      <cp>-0.084 0 0</cp>
      <forward>0 1 0</forward>
      <upward>0 0 1</upward>
      <link_name>iris_demo__iris__rotor_3</link_name>
    </plugin>
    
    <plugin name="arducopter_plugin" filename="libArduCopterPlugin.so">
      <imuName>imu_sensor</imuName>      
      <connectionTimeoutMaxCount>5</connectionTimeoutMaxCount>

      <rotor id="0">
        <vel_p_gain>0.01</vel_p_gain>
        <vel_i_gain>0</vel_i_gain>
        <vel_d_gain>0</vel_d_gain>
        <vel_i_max>0</vel_i_max>
        <vel_i_min>0</vel_i_min>
        <vel_cmd_max>2.0</vel_cmd_max>
        <vel_cmd_min>-2.0</vel_cmd_min>
        <jointName>iris_demo__iris__rotor_0_joint</jointName>
        <turningDirection>ccw</turningDirection>
        <rotorVelocitySlowdownSim>1</rotorVelocitySlowdownSim>
      </rotor>
      <rotor id="1">
        <vel_p_gain>0.01</vel_p_gain>
        <vel_i_gain>0</vel_i_gain>
        <vel_d_gain>0</vel_d_gain>
        <vel_i_max>0</vel_i_max>
        <vel_i_min>0</vel_i_min>
        <vel_cmd_max>2.0</vel_cmd_max>
        <vel_cmd_min>-2.0</vel_cmd_min>
        <jointName>iris_demo__iris__rotor_1_joint</jointName>
        <turningDirection>ccw</turningDirection>
        <rotorVelocitySlowdownSim>1</rotorVelocitySlowdownSim>
      </rotor>
      <rotor id="2">
        <vel_p_gain>0.01</vel_p_gain>
        <vel_i_gain>0</vel_i_gain>
        <vel_d_gain>0</vel_d_gain>
        <vel_i_max>0</vel_i_max>
        <vel_i_min>0</vel_i_min>
        <vel_cmd_max>2.0</vel_cmd_max>
        <vel_cmd_min>-2.0</vel_cmd_min>
        <jointName>iris_demo__iris__rotor_2_joint</jointName>
        <turningDirection>cw</turningDirection>
        <rotorVelocitySlowdownSim>1</rotorVelocitySlowdownSim>
      </rotor>
      <rotor id="3">
        <vel_p_gain>0.01</vel_p_gain>
        <vel_i_gain>0</vel_i_gain>
        <vel_d_gain>0</vel_d_gain>
        <vel_i_max>0</vel_i_max>
        <vel_i_min>0</vel_i_min>
        <vel_cmd_max>2.0</vel_cmd_max>
        <vel_cmd_min>-2.0</vel_cmd_min>
        <jointName>iris_demo__iris__rotor_3_joint</jointName>
        <turningDirection>cw</turningDirection>
        <rotorVelocitySlowdownSim>1</rotorVelocitySlowdownSim>
      </rotor>
    </plugin>

  </gazebo>

  <gazebo reference="iris_demo__hokuyo_link">
    <sensor type="ray" name="laser">
      <pose>0 0 0.02 0 0 0</pose>
      <visualize>true</visualize>
      <update_rate>10</update_rate>
      <ray>
        <scan>
          <horizontal>
            <samples>720</samples>
            <resolution>1</resolution>
            <min_angle>-3.141593</min_angle>
            <max_angle>3.141593</max_angle>
          </horizontal>
        </scan>
        <range>
          <min>0.1</min>
          <max>10</max>
          <resolution>0.1</resolution>
        </range>
        <noise>
          <type>gaussian</type>
          <mean>0.0</mean>
          <stddev>0.01</stddev>
        </noise>
      </ray>
      <plugin name="hokuyo_ros_laser" filename="libgazebo_ros_laser.so">
        <robotNamespace></robotNamespace>
        <topicName>/laser/scan</topicName>
        <frameName>iris_demo__hokuyo_link</frameName>
      </plugin>
    </sensor>
  </gazebo>

  <!--IMU sensor definition -->
  <gazebo reference="iris_demo__iris__iris/imu_link">
    <sensor name="imu_sensor" type="imu">
        <pose>0 0 0 3.141593 0 0</pose>
        <always_on>1</always_on>
        <update_rate>1000.0</update_rate>
      </sensor>
  </gazebo>

  <!--Camera controller -->
  <gazebo reference="iris_demo__gimbal_small_2d__camera">
    <sensor name="camera" type="camera">
          <pose>0 0 0 -1.57 -1.57 0</pose>
          <camera>
            <horizontal_fov>1.0472</horizontal_fov>
            <image>
              <width>640</width>
              <height>480</height>
            </image>
            <clip>
              <near>0.05</near>
              <far>1000</far>
            </clip>
          </camera>
          <always_on>1</always_on>
          <update_rate>10</update_rate>
          <visualize>true</visualize>

          <!--  <plugin name="irlock" filename="libArduCopterIRLockPlugin.so">
              <fiducial>irlock_beacon_01</fiducial>
          </plugin> -->
          <plugin name="camera_controller" filename="libgazebo_ros_camera.so">
            <alwaysOn>true</alwaysOn>
            <updateRate>0.0</updateRate>
            <cameraName>webcam</cameraName>
            <imageTopicName>image_raw</imageTopicName>
            <cameraInfoTopicName>camera_info</cameraInfoTopicName>
            <frameName>iris_demo__gimbal_small_2d__camera</frameName>
            <hackBaseline>0.07</hackBaseline>
            <distortionK1>0.0</distortionK1>
            <distortionK2>0.0</distortionK2>
            <distortionK3>0.0</distortionK3>
            <distortionT1>0.0</distortionT1>
            <distortionT2>0.0</distortionT2>
          </plugin>
    </sensor>
  </gazebo>
</robot>
