<sdf version='1.7'>
  <world name='default'>
    <physics type='ode'>
      <ode>
        <solver>
          <type>quick</type>
          <iters>100</iters>
          <sor>1</sor>
          <use_dynamic_moi_rescaling>0</use_dynamic_moi_rescaling>
        </solver>
        <constraints>
          <cfm>0</cfm>
          <erp>0.9</erp>
          <contact_max_correcting_vel>0.1</contact_max_correcting_vel>
          <contact_surface_layer>0</contact_surface_layer>
        </constraints>
      </ode>
      <real_time_update_rate>-1</real_time_update_rate>
      <max_step_size>0.001</max_step_size>
      <real_time_factor>1</real_time_factor>
    </physics>
    <model name='ground_plane'>
      <static>1</static>
      <link name='link'>
        <collision name='collision'>
          <geometry>
            <plane>
              <normal>0 0 1</normal>
              <size>5000 5000</size>
            </plane>
          </geometry>
          <surface>
            <friction>
              <ode>
                <mu>1</mu>
                <mu2>1</mu2>
              </ode>
              <torsional>
                <ode/>
              </torsional>
            </friction>
            <contact>
              <ode/>
            </contact>
            <bounce/>
          </surface>
          <max_contacts>10</max_contacts>
        </collision>
        <self_collide>0</self_collide>
        <enable_wind>0</enable_wind>
        <kinematic>0</kinematic>
      </link>
    </model>
    <light name='sun' type='directional'>
      <cast_shadows>1</cast_shadows>
      <pose>0 0 10 0 -0 0</pose>
      <diffuse>0.8 0.8 0.8 1</diffuse>
      <specular>0.2 0.2 0.2 1</specular>
      <attenuation>
        <range>1000</range>
        <constant>0.9</constant>
        <linear>0.01</linear>
        <quadratic>0.001</quadratic>
      </attenuation>
      <direction>-0.5 0.1 -0.9</direction>
      <spot>
        <inner_angle>0</inner_angle>
        <outer_angle>0</outer_angle>
        <falloff>0</falloff>
      </spot>
    </light>
    <model name='iris'>
      <frame name='iris_demo::__model__' attached_to='iris_demo::iris::base_link'>
        <pose relative_to='__model__'>0 0 0 0 -0 0</pose>
      </frame>
      <frame name='iris_demo::iris::__model__' attached_to='iris_demo::iris::base_link'>
        <pose relative_to='iris_demo::__model__'>0 0 0.194923 0 -0 0</pose>
      </frame>
      <link name='iris_demo::iris::base_link'>
        <velocity_decay>
          <linear>0</linear>
          <angular>0</angular>
        </velocity_decay>
        <inertial>
          <pose>0 0 0 0 -0 0</pose>
          <mass>1.5</mass>
          <inertia>
            <ixx>0.008</ixx>
            <ixy>0</ixy>
            <ixz>0</ixz>
            <iyy>0.015</iyy>
            <iyz>0</iyz>
            <izz>0.017</izz>
          </inertia>
        </inertial>
        <collision name='base_link_collision'>
          <pose>0 0 -0.08 0 -0 0</pose>
          <geometry>
            <box>
              <size>0.47 0.47 0.23</size>
            </box>
          </geometry>
          <surface>
            <contact>
              <ode>
                <max_vel>100</max_vel>
                <min_depth>0.001</min_depth>
              </ode>
            </contact>
            <friction>
              <ode>
                <mu>100000</mu>
                <mu2>100000</mu2>
              </ode>
              <torsional>
                <ode/>
              </torsional>
            </friction>
            <bounce/>
          </surface>
          <max_contacts>10</max_contacts>
        </collision>
        <visual name='base_link_visual'>
          <geometry>
            <mesh>
              <uri>model://iris_with_standoffs/meshes/iris.dae</uri>
            </mesh>
          </geometry>
          <material>
            <script>
              <name>Gazebo/DarkGrey</name>
              <uri>__default__</uri>
            </script>
          </material>
        </visual>
        <visual name='front_left_leg_visual'>
          <pose>0.123 0.22 -0.11 0 -0 0</pose>
          <geometry>
            <cylinder>
              <radius>0.005</radius>
              <length>0.17</length>
            </cylinder>
          </geometry>
          <material>
            <script>
              <name>Gazebo/FlatBlack</name>
              <uri>file://media/materials/scripts/gazebo.material</uri>
            </script>
          </material>
        </visual>
        <visual name='front_right_leg_visual'>
          <pose>0.123 -0.22 -0.11 0 -0 0</pose>
          <geometry>
            <cylinder>
              <radius>0.005</radius>
              <length>0.17</length>
            </cylinder>
          </geometry>
          <material>
            <script>
              <name>Gazebo/FlatBlack</name>
              <uri>file://media/materials/scripts/gazebo.material</uri>
            </script>
          </material>
        </visual>
        <visual name='rear_left_leg_visual'>
          <pose>-0.14 0.21 -0.11 0 -0 0</pose>
          <geometry>
            <cylinder>
              <radius>0.005</radius>
              <length>0.17</length>
            </cylinder>
          </geometry>
          <material>
            <script>
              <name>Gazebo/FlatBlack</name>
              <uri>file://media/materials/scripts/gazebo.material</uri>
            </script>
          </material>
        </visual>
        <visual name='rear_right_leg_visual'>
          <pose>-0.14 -0.21 -0.11 0 -0 0</pose>
          <geometry>
            <cylinder>
              <radius>0.005</radius>
              <length>0.17</length>
            </cylinder>
          </geometry>
          <material>
            <script>
              <name>Gazebo/FlatBlack</name>
              <uri>file://media/materials/scripts/gazebo.material</uri>
            </script>
          </material>
        </visual>
        <pose relative_to='iris_demo::iris::__model__'>0 0 0 0 -0 0</pose>
        <self_collide>0</self_collide>
        <enable_wind>0</enable_wind>
        <kinematic>0</kinematic>
      </link>
      <link name='iris_demo::iris::iris/ground_truth/odometry_sensorgt_link'>
        <pose relative_to='iris_demo::iris::__model__'>0 0 0 0 -0 0</pose>
        <inertial>
          <pose>0 0 0 0 -0 0</pose>
          <mass>0.15</mass>
          <inertia>
            <ixx>0.0001</ixx>
            <ixy>0</ixy>
            <ixz>0</ixz>
            <iyy>0.0002</iyy>
            <iyz>0</iyz>
            <izz>0.0002</izz>
          </inertia>
        </inertial>
        <self_collide>0</self_collide>
        <enable_wind>0</enable_wind>
        <kinematic>0</kinematic>
      </link>
      <joint name='iris_demo::iris::iris/ground_truth/odometry_sensorgt_joint' type='revolute'>
        <child>iris_demo::iris::iris/ground_truth/odometry_sensorgt_link</child>
        <parent>iris_demo::iris::base_link</parent>
        <axis>
          <xyz expressed_in='iris_demo::iris::__model__'>0 0 1</xyz>
          <limit>
            <lower>0</lower>
            <upper>0</upper>
            <effort>0</effort>
            <velocity>0</velocity>
          </limit>
          <dynamics>
            <damping>1</damping>
            <spring_reference>0</spring_reference>
            <spring_stiffness>0</spring_stiffness>
          </dynamics>
        </axis>
        <physics>
          <ode>
            <implicit_spring_damper>1</implicit_spring_damper>
            <limit>
              <cfm>0</cfm>
              <erp>0.2</erp>
            </limit>
          </ode>
        </physics>
      </joint>
      <link name='iris_demo::iris::iris/imu_link'>
        <inertial>
          <pose>0 0 0 0 -0 0</pose>
          <mass>0.15</mass>
          <inertia>
            <ixx>1e-05</ixx>
            <ixy>0</ixy>
            <ixz>0</ixz>
            <iyy>2e-05</iyy>
            <iyz>0</iyz>
            <izz>2e-05</izz>
          </inertia>
        </inertial>
        <sensor name='imu_sensor' type='imu'>
          <pose>0 0 0 -3.14159 -0 0</pose>
          <always_on>1</always_on>
          <update_rate>1000</update_rate>
          <imu/>
        </sensor>
        <pose relative_to='iris_demo::iris::__model__'>0 0 0 0 -0 0</pose>
        <self_collide>0</self_collide>
        <enable_wind>0</enable_wind>
        <kinematic>0</kinematic>
      </link>
      <joint name='iris_demo::iris::iris/imu_joint' type='revolute'>
        <child>iris_demo::iris::iris/imu_link</child>
        <parent>iris_demo::iris::base_link</parent>
        <axis>
          <xyz expressed_in='iris_demo::iris::__model__'>0 0 1</xyz>
          <limit>
            <lower>0</lower>
            <upper>0</upper>
            <effort>0</effort>
            <velocity>0</velocity>
          </limit>
          <dynamics>
            <damping>1</damping>
            <spring_reference>0</spring_reference>
            <spring_stiffness>0</spring_stiffness>
          </dynamics>
        </axis>
        <physics>
          <ode>
            <implicit_spring_damper>1</implicit_spring_damper>
            <limit>
              <cfm>0</cfm>
              <erp>0.2</erp>
            </limit>
          </ode>
        </physics>
      </joint>
      <link name='iris_demo::iris::rotor_0'>
        <pose relative_to='iris_demo::iris::__model__'>0.13 -0.22 0.023 0 -0 0</pose>
        <inertial>
          <pose>0 0 0 0 -0 0</pose>
          <mass>0.025</mass>
          <inertia>
            <ixx>9.75e-06</ixx>
            <ixy>0</ixy>
            <ixz>0</ixz>
            <iyy>0.000166704</iyy>
            <iyz>0</iyz>
            <izz>0.000167604</izz>
          </inertia>
        </inertial>
        <collision name='rotor_0_collision'>
          <pose>0 0 0 0 -0 0</pose>
          <geometry>
            <cylinder>
              <length>0.005</length>
              <radius>0.1</radius>
            </cylinder>
          </geometry>
          <surface>
            <contact>
              <ode/>
            </contact>
            <friction>
              <ode/>
              <torsional>
                <ode/>
              </torsional>
            </friction>
            <bounce/>
          </surface>
          <max_contacts>10</max_contacts>
        </collision>
        <visual name='rotor_0_visual'>
          <pose>0 0 0 0 -0 0</pose>
          <geometry>
            <mesh>
              <scale>1 1 1</scale>
              <uri>model://iris_with_standoffs/meshes/iris_prop_ccw.dae</uri>
            </mesh>
          </geometry>
          <material>
            <script>
              <name>Gazebo/Blue</name>
              <uri>__default__</uri>
            </script>
          </material>
        </visual>
        <gravity>1</gravity>
        <velocity_decay/>
        <self_collide>0</self_collide>
        <enable_wind>0</enable_wind>
        <kinematic>0</kinematic>
      </link>
      <joint name='iris_demo::iris::rotor_0_joint' type='revolute'>
        <child>iris_demo::iris::rotor_0</child>
        <parent>iris_demo::iris::base_link</parent>
        <axis>
          <xyz expressed_in='iris_demo::iris::__model__'>0 0 1</xyz>
          <limit>
            <lower>-1e+16</lower>
            <upper>1e+16</upper>
          </limit>
          <dynamics>
            <damping>0.004</damping>
            <spring_reference>0</spring_reference>
            <spring_stiffness>0</spring_stiffness>
          </dynamics>
        </axis>
        <physics>
          <ode>
            <implicit_spring_damper>1</implicit_spring_damper>
            <limit>
              <cfm>0</cfm>
              <erp>0.2</erp>
            </limit>
          </ode>
        </physics>
      </joint>
      <link name='iris_demo::iris::rotor_1'>
        <pose relative_to='iris_demo::iris::__model__'>-0.13 0.2 0.023 0 -0 0</pose>
        <inertial>
          <pose>0 0 0 0 -0 0</pose>
          <mass>0.025</mass>
          <inertia>
            <ixx>9.75e-06</ixx>
            <ixy>0</ixy>
            <ixz>0</ixz>
            <iyy>0.000166704</iyy>
            <iyz>0</iyz>
            <izz>0.000167604</izz>
          </inertia>
        </inertial>
        <collision name='rotor_1_collision'>
          <pose>0 0 0 0 -0 0</pose>
          <geometry>
            <cylinder>
              <length>0.005</length>
              <radius>0.1</radius>
            </cylinder>
          </geometry>
          <surface>
            <contact>
              <ode/>
            </contact>
            <friction>
              <ode/>
              <torsional>
                <ode/>
              </torsional>
            </friction>
            <bounce/>
          </surface>
          <max_contacts>10</max_contacts>
        </collision>
        <visual name='rotor_1_visual'>
          <pose>0 0 0 0 -0 0</pose>
          <geometry>
            <mesh>
              <scale>1 1 1</scale>
              <uri>model://iris_with_standoffs/meshes/iris_prop_ccw.dae</uri>
            </mesh>
          </geometry>
          <material>
            <script>
              <name>Gazebo/DarkGrey</name>
              <uri>__default__</uri>
            </script>
          </material>
        </visual>
        <gravity>1</gravity>
        <velocity_decay/>
        <self_collide>0</self_collide>
        <enable_wind>0</enable_wind>
        <kinematic>0</kinematic>
      </link>
      <joint name='iris_demo::iris::rotor_1_joint' type='revolute'>
        <child>iris_demo::iris::rotor_1</child>
        <parent>iris_demo::iris::base_link</parent>
        <axis>
          <xyz expressed_in='iris_demo::iris::__model__'>0 0 1</xyz>
          <limit>
            <lower>-1e+16</lower>
            <upper>1e+16</upper>
          </limit>
          <dynamics>
            <damping>0.004</damping>
            <spring_reference>0</spring_reference>
            <spring_stiffness>0</spring_stiffness>
          </dynamics>
        </axis>
        <physics>
          <ode>
            <implicit_spring_damper>1</implicit_spring_damper>
            <limit>
              <cfm>0</cfm>
              <erp>0.2</erp>
            </limit>
          </ode>
        </physics>
      </joint>
      <link name='iris_demo::iris::rotor_2'>
        <pose relative_to='iris_demo::iris::__model__'>0.13 0.22 0.023 0 -0 0</pose>
        <inertial>
          <pose>0 0 0 0 -0 0</pose>
          <mass>0.025</mass>
          <inertia>
            <ixx>9.75e-06</ixx>
            <ixy>0</ixy>
            <ixz>0</ixz>
            <iyy>0.000166704</iyy>
            <iyz>0</iyz>
            <izz>0.000167604</izz>
          </inertia>
        </inertial>
        <collision name='rotor_2_collision'>
          <pose>0 0 0 0 -0 0</pose>
          <geometry>
            <cylinder>
              <length>0.005</length>
              <radius>0.1</radius>
            </cylinder>
          </geometry>
          <surface>
            <contact>
              <ode/>
            </contact>
            <friction>
              <ode/>
              <torsional>
                <ode/>
              </torsional>
            </friction>
            <bounce/>
          </surface>
          <max_contacts>10</max_contacts>
        </collision>
        <visual name='rotor_2_visual'>
          <pose>0 0 0 0 -0 0</pose>
          <geometry>
            <mesh>
              <scale>1 1 1</scale>
              <uri>model://iris_with_standoffs/meshes/iris_prop_cw.dae</uri>
            </mesh>
          </geometry>
          <material>
            <script>
              <name>Gazebo/Blue</name>
              <uri>__default__</uri>
            </script>
          </material>
        </visual>
        <gravity>1</gravity>
        <velocity_decay/>
        <self_collide>0</self_collide>
        <enable_wind>0</enable_wind>
        <kinematic>0</kinematic>
      </link>
      <joint name='iris_demo::iris::rotor_2_joint' type='revolute'>
        <child>iris_demo::iris::rotor_2</child>
        <parent>iris_demo::iris::base_link</parent>
        <axis>
          <xyz expressed_in='iris_demo::iris::__model__'>0 0 1</xyz>
          <limit>
            <lower>-1e+16</lower>
            <upper>1e+16</upper>
          </limit>
          <dynamics>
            <damping>0.004</damping>
            <spring_reference>0</spring_reference>
            <spring_stiffness>0</spring_stiffness>
          </dynamics>
        </axis>
        <physics>
          <ode>
            <implicit_spring_damper>1</implicit_spring_damper>
            <limit>
              <cfm>0</cfm>
              <erp>0.2</erp>
            </limit>
          </ode>
        </physics>
      </joint>
      <link name='iris_demo::iris::rotor_3'>
        <pose relative_to='iris_demo::iris::__model__'>-0.13 -0.2 0.023 0 -0 0</pose>
        <inertial>
          <pose>0 0 0 0 -0 0</pose>
          <mass>0.025</mass>
          <inertia>
            <ixx>9.75e-06</ixx>
            <ixy>0</ixy>
            <ixz>0</ixz>
            <iyy>0.000166704</iyy>
            <iyz>0</iyz>
            <izz>0.000167604</izz>
          </inertia>
        </inertial>
        <collision name='rotor_3_collision'>
          <pose>0 0 0 0 -0 0</pose>
          <geometry>
            <cylinder>
              <length>0.005</length>
              <radius>0.1</radius>
            </cylinder>
          </geometry>
          <surface>
            <contact>
              <ode/>
            </contact>
            <friction>
              <ode/>
              <torsional>
                <ode/>
              </torsional>
            </friction>
            <bounce/>
          </surface>
          <max_contacts>10</max_contacts>
        </collision>
        <visual name='rotor_3_visual'>
          <pose>0 0 0 0 -0 0</pose>
          <geometry>
            <mesh>
              <scale>1 1 1</scale>
              <uri>model://iris_with_standoffs/meshes/iris_prop_cw.dae</uri>
            </mesh>
          </geometry>
          <material>
            <script>
              <name>Gazebo/DarkGrey</name>
              <uri>__default__</uri>
            </script>
          </material>
        </visual>
        <gravity>1</gravity>
        <velocity_decay/>
        <self_collide>0</self_collide>
        <enable_wind>0</enable_wind>
        <kinematic>0</kinematic>
      </link>
      <joint name='iris_demo::iris::rotor_3_joint' type='revolute'>
        <child>iris_demo::iris::rotor_3</child>
        <parent>iris_demo::iris::base_link</parent>
        <axis>
          <xyz expressed_in='iris_demo::iris::__model__'>0 0 1</xyz>
          <limit>
            <lower>-1e+16</lower>
            <upper>1e+16</upper>
          </limit>
          <dynamics>
            <damping>0.004</damping>
            <spring_reference>0</spring_reference>
            <spring_stiffness>0</spring_stiffness>
          </dynamics>
        </axis>
        <physics>
          <ode>
            <implicit_spring_damper>1</implicit_spring_damper>
            <limit>
              <cfm>0</cfm>
              <erp>0.2</erp>
            </limit>
          </ode>
        </physics>
      </joint>
      <static>0</static>
      <plugin name='rotor_0_blade_1' filename='libLiftDragPlugin.so'>
        <a0>0.1</a0>
        <alpha_stall>1.4</alpha_stall>
        <cla>0.2500</cla>
        <cda>0.10</cda>
        <cma>0.00</cma>
        <cla_stall>-0.025</cla_stall>
        <cda_stall>0.0</cda_stall>
        <cma_stall>0.0</cma_stall>
        <area>0.2</area>
        <air_density>1.2041</air_density>
        <cp>0.084 0 0</cp>
        <forward>0 1 0</forward>
        <upward>0 0 1</upward>
        <link_name>iris_demo::iris::rotor_0</link_name>
      </plugin>
      <plugin name='rotor_0_blade_2' filename='libLiftDragPlugin.so'>
        <a0>0.1</a0>
        <alpha_stall>1.4</alpha_stall>
        <cla>0.2500</cla>
        <cda>0.10</cda>
        <cma>0.00</cma>
        <cla_stall>-0.025</cla_stall>
        <cda_stall>0.0</cda_stall>
        <cma_stall>0.0</cma_stall>
        <area>0.2</area>
        <air_density>1.2041</air_density>
        <cp>-0.084 0 0</cp>
        <forward>0 -1 0</forward>
        <upward>0 0 1</upward>
        <link_name>iris_demo::iris::rotor_0</link_name>
      </plugin>
      <plugin name='rotor_1_blade_1' filename='libLiftDragPlugin.so'>
        <a0>0.1</a0>
        <alpha_stall>1.4</alpha_stall>
        <cla>0.2500</cla>
        <cda>0.10</cda>
        <cma>0.00</cma>
        <cla_stall>-0.025</cla_stall>
        <cda_stall>0.0</cda_stall>
        <cma_stall>0.0</cma_stall>
        <area>0.2</area>
        <air_density>1.2041</air_density>
        <cp>0.084 0 0</cp>
        <forward>0 1 0</forward>
        <upward>0 0 1</upward>
        <link_name>iris_demo::iris::rotor_1</link_name>
      </plugin>
      <plugin name='rotor_1_blade_2' filename='libLiftDragPlugin.so'>
        <a0>0.1</a0>
        <alpha_stall>1.4</alpha_stall>
        <cla>0.2500</cla>
        <cda>0.10</cda>
        <cma>0.00</cma>
        <cla_stall>-0.025</cla_stall>
        <cda_stall>0.0</cda_stall>
        <cma_stall>0.0</cma_stall>
        <area>0.2</area>
        <air_density>1.2041</air_density>
        <cp>-0.084 0 0</cp>
        <forward>0 -1 0</forward>
        <upward>0 0 1</upward>
        <link_name>iris_demo::iris::rotor_1</link_name>
      </plugin>
      <plugin name='rotor_2_blade_1' filename='libLiftDragPlugin.so'>
        <a0>0.1</a0>
        <alpha_stall>1.4</alpha_stall>
        <cla>0.2500</cla>
        <cda>0.10</cda>
        <cma>0.00</cma>
        <cla_stall>-0.025</cla_stall>
        <cda_stall>0.0</cda_stall>
        <cma_stall>0.0</cma_stall>
        <area>0.2</area>
        <air_density>1.2041</air_density>
        <cp>0.084 0 0</cp>
        <forward>0 -1 0</forward>
        <upward>0 0 1</upward>
        <link_name>iris_demo::iris::rotor_2</link_name>
      </plugin>
      <plugin name='rotor_2_blade_2' filename='libLiftDragPlugin.so'>
        <a0>0.1</a0>
        <alpha_stall>1.4</alpha_stall>
        <cla>0.2500</cla>
        <cda>0.10</cda>
        <cma>0.00</cma>
        <cla_stall>-0.025</cla_stall>
        <cda_stall>0.0</cda_stall>
        <cma_stall>0.0</cma_stall>
        <area>0.2</area>
        <air_density>1.2041</air_density>
        <cp>-0.084 0 0</cp>
        <forward>0 1 0</forward>
        <upward>0 0 1</upward>
        <link_name>iris_demo::iris::rotor_2</link_name>
      </plugin>
      <plugin name='rotor_3_blade_1' filename='libLiftDragPlugin.so'>
        <a0>0.1</a0>
        <alpha_stall>1.4</alpha_stall>
        <cla>0.2500</cla>
        <cda>0.10</cda>
        <cma>0.00</cma>
        <cla_stall>-0.025</cla_stall>
        <cda_stall>0.0</cda_stall>
        <cma_stall>0.0</cma_stall>
        <area>0.2</area>
        <air_density>1.2041</air_density>
        <cp>0.084 0 0</cp>
        <forward>0 -1 0</forward>
        <upward>0 0 1</upward>
        <link_name>iris_demo::iris::rotor_3</link_name>
      </plugin>
      <plugin name='rotor_3_blade_2' filename='libLiftDragPlugin.so'>
        <a0>0.1</a0>
        <alpha_stall>1.4</alpha_stall>
        <cla>0.2500</cla>
        <cda>0.10</cda>
        <cma>0.00</cma>
        <cla_stall>-0.025</cla_stall>
        <cda_stall>0.0</cda_stall>
        <cma_stall>0.0</cma_stall>
        <area>0.2</area>
        <air_density>1.2041</air_density>
        <cp>-0.084 0 0</cp>
        <forward>0 1 0</forward>
        <upward>0 0 1</upward>
        <link_name>iris_demo::iris::rotor_3</link_name>
      </plugin>
      <plugin name='arducopter_plugin' filename='libArduCopterPlugin.so'>
        <imuName>iris_demo::iris::iris/imu_link::imu_sensor</imuName>
        <connectionTimeoutMaxCount>5</connectionTimeoutMaxCount>
        <rotor id='0'>
          <vel_p_gain>0.01</vel_p_gain>
          <vel_i_gain>0</vel_i_gain>
          <vel_d_gain>0</vel_d_gain>
          <vel_i_max>0</vel_i_max>
          <vel_i_min>0</vel_i_min>
          <vel_cmd_max>2.0</vel_cmd_max>
          <vel_cmd_min>-2.0</vel_cmd_min>
          <jointName>iris_demo::iris::rotor_0_joint</jointName>
          <turningDirection>ccw</turningDirection>
          <rotorVelocitySlowdownSim>1</rotorVelocitySlowdownSim>
        </rotor>
        <rotor id='1'>
          <vel_p_gain>0.01</vel_p_gain>
          <vel_i_gain>0</vel_i_gain>
          <vel_d_gain>0</vel_d_gain>
          <vel_i_max>0</vel_i_max>
          <vel_i_min>0</vel_i_min>
          <vel_cmd_max>2.0</vel_cmd_max>
          <vel_cmd_min>-2.0</vel_cmd_min>
          <jointName>iris_demo::iris::rotor_1_joint</jointName>
          <turningDirection>ccw</turningDirection>
          <rotorVelocitySlowdownSim>1</rotorVelocitySlowdownSim>
        </rotor>
        <rotor id='2'>
          <vel_p_gain>0.01</vel_p_gain>
          <vel_i_gain>0</vel_i_gain>
          <vel_d_gain>0</vel_d_gain>
          <vel_i_max>0</vel_i_max>
          <vel_i_min>0</vel_i_min>
          <vel_cmd_max>2.0</vel_cmd_max>
          <vel_cmd_min>-2.0</vel_cmd_min>
          <jointName>iris_demo::iris::rotor_2_joint</jointName>
          <turningDirection>cw</turningDirection>
          <rotorVelocitySlowdownSim>1</rotorVelocitySlowdownSim>
        </rotor>
        <rotor id='3'>
          <vel_p_gain>0.01</vel_p_gain>
          <vel_i_gain>0</vel_i_gain>
          <vel_d_gain>0</vel_d_gain>
          <vel_i_max>0</vel_i_max>
          <vel_i_min>0</vel_i_min>
          <vel_cmd_max>2.0</vel_cmd_max>
          <vel_cmd_min>-2.0</vel_cmd_min>
          <jointName>iris_demo::iris::rotor_3_joint</jointName>
          <turningDirection>cw</turningDirection>
          <rotorVelocitySlowdownSim>1</rotorVelocitySlowdownSim>
        </rotor>
      </plugin>
      <pose>0 0 0 0 -0 0</pose>
      <joint name='hokuyo_joint' type='fixed'>
        <pose>0 0 0 0 -0 0</pose>
        <parent>iris::iris_demo::iris::base_link</parent>
        <child>hokuyo_link</child>
      </joint>
      <link name='hokuyo_link'>
        <pose>0 0 0 0 -0 0</pose>
        <collision name='collision'>
          <pose>0 0 0.3 0 -0 0</pose>
          <geometry>
            <box>
              <size>0.1 0.1 0.1</size>
            </box>
          </geometry>
          <max_contacts>10</max_contacts>
          <surface>
            <contact>
              <ode/>
            </contact>
            <bounce/>
            <friction>
              <torsional>
                <ode/>
              </torsional>
              <ode/>
            </friction>
          </surface>
        </collision>
        <visual name='visual'>
          <pose>0 0 0.27 0 -0 0</pose>
          <geometry>
            <mesh>
              <uri>model://hokuyo/meshes/hokuyo.dae</uri>
            </mesh>
          </geometry>
        </visual>
        <inertial>
          <mass>0.016</mass>
          <inertia>
            <ixx>0.0001</ixx>
            <ixy>0</ixy>
            <ixz>0</ixz>
            <iyy>0.0001</iyy>
            <iyz>0</iyz>
            <izz>0.0001</izz>
          </inertia>
          <pose>0 0 0 0 -0 0</pose>
        </inertial>
        <sensor name='laser' type='ray'>
          <pose>0 0 0.3 0 -0 1.57005</pose>
          <visualize>1</visualize>
          <update_rate>10</update_rate>
          <ray>
            <scan>
              <horizontal>
                <samples>1024</samples>
                <resolution>1</resolution>
                <min_angle>-3.14159</min_angle>
                <max_angle>3.14159</max_angle>
              </horizontal>
              <vertical>
                <samples>1</samples>
                <min_angle>0</min_angle>
                <max_angle>0</max_angle>
              </vertical>
            </scan>
            <range>
              <min>0.35</min>
              <max>5</max>
              <resolution>0.1</resolution>
            </range>
            <noise>
              <type>gaussian</type>
              <mean>0</mean>
              <stddev>0.01</stddev>
            </noise>
          </ray>
          <plugin name='hokuyo_ros_laser' filename='libgazebo_ros_laser.so'>
            <robotNamespace/>
            <topicName>/laser/scan</topicName>
            <frameName>iris_demo__hokuyo_link</frameName>
          </plugin>
        </sensor>
        <self_collide>0</self_collide>
        <enable_wind>0</enable_wind>
        <kinematic>0</kinematic>
      </link>
      <link name='base_sonar_top'>
        <pose>0.05 0 0.24 0 -1.57005 0</pose>
        <visual name='visual'>
          <geometry>
            <box>
              <size>0.01 0.01 0.01</size>
            </box>
          </geometry>
        </visual>
        <inertial>
          <mass>0.01</mass>
          <inertia>
            <ixx>0.001</ixx>
            <ixy>0</ixy>
            <ixz>0</ixz>
            <iyy>0.001</iyy>
            <iyz>0</iyz>
            <izz>0.001</izz>
          </inertia>
          <pose>0 0 0 0 -0 0</pose>
        </inertial>
        <sensor name='sonar_sensor' type='ray'>
          <visualize>1</visualize>
          <update_rate>10</update_rate>
          <ray>
            <scan>
              <horizontal>
                <samples>10</samples>
                <resolution>1</resolution>
                <min_angle>-0.14835</min_angle>
                <max_angle>0.14835</max_angle>
              </horizontal>
              <vertical>
                <samples>10</samples>
                <resolution>1</resolution>
                <min_angle>-0.14835</min_angle>
                <max_angle>0.14835</max_angle>
              </vertical>
            </scan>
            <range>
              <min>0.12</min>
              <max>2.5</max>
              <resolution>0.02</resolution>
            </range>
          </ray>
          <plugin name='gazebo_ros_range2' filename='libgazebo_ros_range.so'>
            <gaussianNoise>0.005</gaussianNoise>
            <alwaysOn>1</alwaysOn>
            <updateRate>50</updateRate>
            <topicName>/distance_sensor/top</topicName>
            <frameName>base_sonar_top</frameName>
            <fov>0.2967</fov>
          </plugin>
        </sensor>
        <self_collide>0</self_collide>
        <enable_wind>0</enable_wind>
        <kinematic>0</kinematic>
      </link>
      <joint name='base_sonar_joint_top' type='fixed'>
        <pose>0 0 0 0 -0 0</pose>
        <parent>iris_demo::iris::base_link</parent>
        <child>base_sonar_top</child>
        <axis>
          <limit>
            <lower>0</lower>
            <upper>0</upper>
          </limit>
          <xyz>0 0 1</xyz>
          <use_parent_model_frame>1</use_parent_model_frame>
        </axis>
      </joint>
      <link name='base_sonar_bottom'>
        <pose>0 0 0.15 0 1.57005 0</pose>
        <visual name='visual'>
          <geometry>
            <box>
              <size>0.01 0.01 0.01</size>
            </box>
          </geometry>
        </visual>
        <inertial>
          <mass>0.01</mass>
          <inertia>
            <ixx>0.001</ixx>
            <ixy>0</ixy>
            <ixz>0</ixz>
            <iyy>0.001</iyy>
            <iyz>0</iyz>
            <izz>0.001</izz>
          </inertia>
          <pose>0 0 0 0 -0 0</pose>
        </inertial>
        <sensor name='sonar_sensor' type='ray'>
          <visualize>1</visualize>
          <update_rate>10</update_rate>
          <ray>
            <scan>
              <horizontal>
                <samples>10</samples>
                <resolution>1</resolution>
                <min_angle>-0.14835</min_angle>
                <max_angle>0.14835</max_angle>
              </horizontal>
              <vertical>
                <samples>10</samples>
                <resolution>1</resolution>
                <min_angle>-0.14835</min_angle>
                <max_angle>0.14835</max_angle>
              </vertical>
            </scan>
            <range>
              <min>0.16</min>
              <max>2.5</max>
              <resolution>0.02</resolution>
            </range>
          </ray>
          <plugin name='gazebo_ros_range2' filename='libgazebo_ros_range.so'>
            <gaussianNoise>0.005</gaussianNoise>
            <alwaysOn>1</alwaysOn>
            <updateRate>50</updateRate>
            <topicName>/distance_sensor/bottom</topicName>
            <frameName>base_sonar_bottom</frameName>
            <fov>0.2967</fov>
          </plugin>
        </sensor>
        <self_collide>0</self_collide>
        <enable_wind>0</enable_wind>
        <kinematic>0</kinematic>
      </link>
      <joint name='base_sonar_joint_bottom' type='fixed'>
        <pose>0 0 0 0 -0 0</pose>
        <parent>iris_demo::iris::base_link</parent>
        <child>base_sonar_bottom</child>
        <axis>
          <limit>
            <lower>0</lower>
            <upper>0</upper>
          </limit>
          <xyz>0 0 1</xyz>
          <use_parent_model_frame>1</use_parent_model_frame>
        </axis>
      </joint>
    </model>
    <gravity>0 0 -9.8</gravity>
    <magnetic_field>6e-06 2.3e-05 -4.2e-05</magnetic_field>
    <atmosphere type='adiabatic'/>
    <scene>
      <ambient>0.4 0.4 0.4 1</ambient>
      <background>0.7 0.7 0.7 1</background>
      <shadows>1</shadows>
    </scene>
    <wind/>
    <spherical_coordinates>
      <surface_model>EARTH_WGS84</surface_model>
      <latitude_deg>0</latitude_deg>
      <longitude_deg>0</longitude_deg>
      <elevation>0</elevation>
      <heading_deg>0</heading_deg>
    </spherical_coordinates>
    <state world_name='default'>
      <sim_time>4700 622000000</sim_time>
      <real_time>702 983332715</real_time>
      <wall_time>1701720111 512678393</wall_time>
      <iterations>702025</iterations>
      <model name='ground_plane'>
        <pose>0 0 0 0 -0 0</pose>
        <scale>1 1 1</scale>
        <link name='link'>
          <pose>0 0 0 0 -0 0</pose>
          <velocity>0 0 0 0 -0 0</velocity>
          <acceleration>0 0 0 0 -0 0</acceleration>
          <wrench>0 0 0 0 -0 0</wrench>
        </link>
      </model>
      <model name='iris'>
        <pose>-7e-06 9.1e-05 -0.000423 -0.002128 0 -4.8e-05</pose>
        <scale>1 1 1</scale>
        <link name='base_sonar_bottom'>
          <pose>-7e-06 0.000411 0.149577 -1.23341 1.56854 -1.23345</pose>
          <velocity>6e-06 4e-06 1e-06 -1e-05 -4.9e-05 1.7e-05</velocity>
          <acceleration>0.02797 0.008523 0.001972 -0.019585 -0.00636 0.037514</acceleration>
          <wrench>0.00028 8.5e-05 2e-05 0 -0 0</wrench>
        </link>
        <link name='base_sonar_top'>
          <pose>0.049993 0.0006 0.239576 -1.23344 -1.56854 1.2334</pose>
          <velocity>1e-06 6e-06 3e-06 -1e-05 -4.9e-05 1.7e-05</velocity>
          <acceleration>0.027796 0.012532 0.002008 -0.019939 -0.006013 0.037656</acceleration>
          <wrench>0.000278 0.000125 2e-05 0 -0 0</wrench>
        </link>
        <link name='hokuyo_link'>
          <pose>-7e-06 9.1e-05 -0.000423 -0.002128 0 -4.8e-05</pose>
          <velocity>1.9e-05 4e-06 1e-06 -1e-05 -4.9e-05 1.7e-05</velocity>
          <acceleration>0.040872 0.0082 0.001975 -0.019776 -0.006415 0.037668</acceleration>
          <wrench>0.000654 0.000131 3.2e-05 0 -0 0</wrench>
        </link>
        <link name='iris_demo::iris::base_link'>
          <pose>-7e-06 0.000506 0.1945 -0.002128 0 -4.8e-05</pose>
          <velocity>-0 4e-06 1e-06 -2.1e-05 -0 0</velocity>
          <acceleration>0.019957 0.008051 0.001788 -0.042118 0.100587 0.000663</acceleration>
          <wrench>0.029936 0.012077 0.002682 0 -0 0</wrench>
        </link>
        <link name='iris_demo::iris::iris/ground_truth/odometry_sensorgt_link'>
          <pose>-7e-06 0.000506 0.1945 -0.002128 0 -4.8e-05</pose>
          <velocity>4e-06 5e-06 1e-06 -1e-05 -4.8e-05 1.2e-05</velocity>
          <acceleration>0.028476 0.009726 0.002024 -0.021461 -0.005496 0.033919</acceleration>
          <wrench>0.004271 0.001459 0.000304 0 -0 0</wrench>
        </link>
        <link name='iris_demo::iris::iris/imu_link'>
          <pose>-7e-06 0.000506 0.1945 -0.002128 0 -4.8e-05</pose>
          <velocity>4e-06 5e-06 1e-06 -1e-05 -4.8e-05 1.2e-05</velocity>
          <acceleration>0.028246 0.009645 0.002004 -0.02143 -0.005551 0.033912</acceleration>
          <wrench>0.004237 0.001447 0.000301 0 -0 0</wrench>
        </link>
        <link name='iris_demo::iris::rotor_0'>
          <pose>0.129983 -0.219451 0.217968 9.7e-05 -0.002125 -1.61625</pose>
          <velocity>6e-06 7e-06 1e-05 -1e-05 -4.7e-05 0</velocity>
          <acceleration>0.03628 0.01505 0.007407 -0.004 -0.064097 0.000106</acceleration>
          <wrench>0.000907 0.000376 0.000185 0 -0 0</wrench>
        </link>
        <link name='iris_demo::iris::rotor_1'>
          <pose>-0.129997 0.200561 0.217074 -0.001721 -0.001251 -0.628558</pose>
          <velocity>-1e-06 3e-06 -7e-06 -1e-05 -4.5e-05 0</velocity>
          <acceleration>0.020367 0.005185 -0.002988 -0.032852 0.025408 -8.6e-05</acceleration>
          <wrench>0.000509 0.00013 -7.5e-05 0 -0 0</wrench>
        </link>
        <link name='iris_demo::iris::rotor_2'>
          <pose>0.130004 0.220548 0.217031 -0.000161 -0.002122 -1.49525</pose>
          <velocity>-1e-06 7e-06 5e-06 -1e-05 -5e-05 0</velocity>
          <acceleration>0.0195 0.014934 -0.001946 0.008889 -0.142328 0.000272</acceleration>
          <wrench>0.000487 0.000373 -4.9e-05 0 -0 0</wrench>
        </link>
        <link name='iris_demo::iris::rotor_3'>
          <pose>-0.130017 -0.199438 0.217925 -0.001628 -0.00137 -0.699653</pose>
          <velocity>6e-06 3e-06 -3e-06 -1e-05 -4.6e-05 0</velocity>
          <acceleration>0.035451 0.004994 0.00532 -0.024695 0.021308 -7.7e-05</acceleration>
          <wrench>0.000886 0.000125 0.000133 0 -0 0</wrench>
        </link>
      </model>
      <model name='shelf'>
        <pose>-1.82986 3.71247 0 0 -0 0</pose>
        <scale>1 1 1</scale>
        <link name='shelf_base'>
          <pose>-2.32986 3.71247 0 0 -0 0</pose>
          <velocity>0 0 0 0 -0 0</velocity>
          <acceleration>0 0 0 0 -0 0</acceleration>
          <wrench>0 0 0 0 -0 0</wrench>
        </link>
      </model>
      <model name='shelf_clone'>
        <pose>3.96388 3.56146 0 0 -0 0</pose>
        <scale>1 1 1</scale>
        <link name='shelf_base'>
          <pose>3.46388 3.56146 0 0 -0 0</pose>
          <velocity>0 0 0 0 -0 0</velocity>
          <acceleration>0 0 0 0 -0 0</acceleration>
          <wrench>0 0 0 0 -0 0</wrench>
        </link>
      </model>
      <model name='shelf_clone_0'>
        <pose>0.378551 6.6375 0 0 -0 0</pose>
        <scale>1 1 1</scale>
        <link name='shelf_base'>
          <pose>-0.121449 6.6375 0 0 -0 0</pose>
          <velocity>0 0 0 0 -0 0</velocity>
          <acceleration>0 0 0 0 -0 0</acceleration>
          <wrench>0 0 0 0 -0 0</wrench>
        </link>
      </model>
      <model name='shelf_clone_1'>
        <pose>-1.78419 3.70359 1.81663 0 -0 0</pose>
        <scale>1 1 1</scale>
        <link name='shelf_base'>
          <pose>-2.28419 3.70359 1.81663 0 -0 0</pose>
          <velocity>0 0 0 0 -0 0</velocity>
          <acceleration>0 0 0 0 -0 0</acceleration>
          <wrench>0 0 0 0 -0 0</wrench>
        </link>
      </model>
      <model name='shelf_clone_2'>
        <pose>0.365305 6.64863 1.81684 0 -0 0</pose>
        <scale>1 1 1</scale>
        <link name='shelf_base'>
          <pose>-0.134695 6.64863 1.81684 0 -0 0</pose>
          <velocity>0 0 0 0 -0 0</velocity>
          <acceleration>0 0 0 0 -0 0</acceleration>
          <wrench>0 0 0 0 -0 0</wrench>
        </link>
      </model>
      <model name='shelf_clone_3'>
        <pose>3.92911 3.54756 1.84403 0 -0 0</pose>
        <scale>1 1 1</scale>
        <link name='shelf_base'>
          <pose>3.42911 3.54756 1.84403 0 -0 0</pose>
          <velocity>0 0 0 0 -0 0</velocity>
          <acceleration>0 0 0 0 -0 0</acceleration>
          <wrench>0 0 0 0 -0 0</wrench>
        </link>
      </model>
      <model name='warehouse'>
        <pose>0.45013 1.22941 -0.090471 0 -0 0</pose>
        <scale>1 1 1</scale>
        <link name='warehouse_base'>
          <pose>0.45013 1.22941 -0.090471 0 -0 0</pose>
          <velocity>0 0 0 0 -0 0</velocity>
          <acceleration>0 0 0 0 -0 0</acceleration>
          <wrench>0 0 0 0 -0 0</wrench>
        </link>
      </model>
      <light name='sun'>
        <pose>0 0 10 0 -0 0</pose>
      </light>
      <light name='user_spot_light_0'>
        <pose>0.090026 -0.966713 10 0 -0 0</pose>
      </light>
      <light name='user_spot_light_0_clone'>
        <pose>0.430291 7.89344 10 0 -0 0</pose>
      </light>
      <light name='user_spot_light_0_clone_0'>
        <pose>-5.71325 4.28744 10 0 -0 0</pose>
      </light>
      <light name='user_spot_light_0_clone_1'>
        <pose>6.11006 4.8761 10 0 -0 0</pose>
      </light>
      <light name='user_spot_light_0_clone_2'>
        <pose>-5.69627 5.14657 10 0 -0 0</pose>
      </light>
    </state>
    <model name='warehouse'>
      <pose>0.947668 -2.63575 0 0 -0 0</pose>
      <self_collide>0</self_collide>
      <link name='warehouse_base'>
        <pose>0 0 0 0 -0 0</pose>
        <collision name='warehouse_collision'>
          <pose>0 0 0 0 -0 0</pose>
          <geometry>
            <mesh>
              <scale>1 1 1</scale>
              <uri>/home/dan/.gazebo/models/Warehouse/meshes/warehouse_colision.stl</uri>
            </mesh>
          </geometry>
          <max_contacts>10</max_contacts>
          <surface>
            <contact>
              <ode/>
            </contact>
            <bounce/>
            <friction>
              <torsional>
                <ode/>
              </torsional>
              <ode/>
            </friction>
          </surface>
        </collision>
        <visual name='warehouse_visual'>
          <pose>0 0 0 0 -0 0</pose>
          <geometry>
            <mesh>
              <scale>1 1 1</scale>
              <uri>/home/dan/.gazebo/models/Warehouse/meshes/warehouse.dae</uri>
            </mesh>
          </geometry>
        </visual>
        <visual name='drop_area_visual'>
          <pose>0 0 0.101 0 -0 0</pose>
          <geometry>
            <mesh>
              <scale>1 1 1</scale>
              <uri>/home/dan/.gazebo/models/Warehouse/meshes/warehouse.dae</uri>
              <submesh>
                <name>drop1</name>
                <center>1</center>
              </submesh>
            </mesh>
          </geometry>
        </visual>
        <self_collide>0</self_collide>
        <enable_wind>0</enable_wind>
        <kinematic>0</kinematic>
      </link>
      <static>1</static>
    </model>
    <model name='shelf'>
      <pose>-1.79625 3.69579 0 0 -0 0</pose>
      <self_collide>1</self_collide>
      <link name='shelf_base'>
        <pose>-0.5 0 0 0 -0 0</pose>
        <collision name='shelf_chassi_collision'>
          <pose>0 0 0.9 0 -0 0</pose>
          <geometry>
            <box>
              <size>3.6 0.6 1.8</size>
            </box>
          </geometry>
          <max_contacts>10</max_contacts>
          <surface>
            <contact>
              <ode/>
            </contact>
            <bounce/>
            <friction>
              <torsional>
                <ode/>
              </torsional>
              <ode/>
            </friction>
          </surface>
        </collision>
        <visual name='shelf_chassi_visual'>
          <pose>0 0 0 0 -0 0</pose>
          <geometry>
            <mesh>
              <scale>0.2 0.3 0.3</scale>
              <uri>/home/dan/.ignition/fuel/fuel.gazebosim.org/ngd1004/models/shelf/1/meshes/shelf_big_movai.dae</uri>
            </mesh>
          </geometry>
        </visual>
        <self_collide>1</self_collide>
        <enable_wind>0</enable_wind>
        <kinematic>0</kinematic>
      </link>
      <static>1</static>
    </model>
    <model name='shelf_clone'>
      <pose>3.96388 3.56146 0 0 -0 0</pose>
      <self_collide>1</self_collide>
      <link name='shelf_base'>
        <pose>-0.5 0 0 0 -0 0</pose>
        <collision name='shelf_chassi_collision'>
          <pose>0 0 0.9 0 -0 0</pose>
          <geometry>
            <box>
              <size>3.6 0.6 1.8</size>
            </box>
          </geometry>
          <max_contacts>10</max_contacts>
          <surface>
            <contact>
              <ode/>
            </contact>
            <bounce/>
            <friction>
              <torsional>
                <ode/>
              </torsional>
              <ode/>
            </friction>
          </surface>
        </collision>
        <visual name='shelf_chassi_visual'>
          <pose>0 0 0 0 -0 0</pose>
          <geometry>
            <mesh>
              <scale>0.2 0.3 0.3</scale>
              <uri>/home/dan/.ignition/fuel/fuel.gazebosim.org/ngd1004/models/shelf/1/meshes/shelf_big_movai.dae</uri>
            </mesh>
          </geometry>
        </visual>
        <self_collide>1</self_collide>
        <enable_wind>0</enable_wind>
        <kinematic>0</kinematic>
      </link>
      <static>1</static>
    </model>
    <model name='shelf_clone_0'>
      <pose>0.378551 6.6375 0 0 -0 0</pose>
      <self_collide>1</self_collide>
      <link name='shelf_base'>
        <pose>-0.5 0 0 0 -0 0</pose>
        <collision name='shelf_chassi_collision'>
          <pose>0 0 0.9 0 -0 0</pose>
          <geometry>
            <box>
              <size>3.6 0.6 1.8</size>
            </box>
          </geometry>
          <max_contacts>10</max_contacts>
          <surface>
            <contact>
              <ode/>
            </contact>
            <bounce/>
            <friction>
              <torsional>
                <ode/>
              </torsional>
              <ode/>
            </friction>
          </surface>
        </collision>
        <visual name='shelf_chassi_visual'>
          <pose>0 0 0 0 -0 0</pose>
          <geometry>
            <mesh>
              <scale>0.2 0.3 0.3</scale>
              <uri>/home/dan/.ignition/fuel/fuel.gazebosim.org/ngd1004/models/shelf/1/meshes/shelf_big_movai.dae</uri>
            </mesh>
          </geometry>
        </visual>
        <self_collide>1</self_collide>
        <enable_wind>0</enable_wind>
        <kinematic>0</kinematic>
      </link>
      <static>1</static>
    </model>
    <model name='shelf_clone_1'>
      <pose>-1.78419 3.63429 0 0 -0 0</pose>
      <self_collide>1</self_collide>
      <link name='shelf_base'>
        <pose>-0.5 0 0 0 -0 0</pose>
        <collision name='shelf_chassi_collision'>
          <pose>0 0 0.9 0 -0 0</pose>
          <geometry>
            <box>
              <size>3.6 0.6 1.8</size>
            </box>
          </geometry>
          <max_contacts>10</max_contacts>
          <surface>
            <contact>
              <ode/>
            </contact>
            <bounce/>
            <friction>
              <torsional>
                <ode/>
              </torsional>
              <ode/>
            </friction>
          </surface>
        </collision>
        <visual name='shelf_chassi_visual'>
          <pose>0 0 0 0 -0 0</pose>
          <geometry>
            <mesh>
              <scale>0.2 0.3 0.3</scale>
              <uri>/home/dan/.ignition/fuel/fuel.gazebosim.org/ngd1004/models/shelf/1/meshes/shelf_big_movai.dae</uri>
            </mesh>
          </geometry>
        </visual>
        <self_collide>1</self_collide>
        <enable_wind>0</enable_wind>
        <kinematic>0</kinematic>
      </link>
      <static>1</static>
    </model>
    <model name='shelf_clone_2'>
      <pose>0.365305 6.54488 0 0 -0 0</pose>
      <self_collide>1</self_collide>
      <link name='shelf_base'>
        <pose>-0.5 0 0 0 -0 0</pose>
        <collision name='shelf_chassi_collision'>
          <pose>0 0 0.9 0 -0 0</pose>
          <geometry>
            <box>
              <size>3.6 0.6 1.8</size>
            </box>
          </geometry>
          <max_contacts>10</max_contacts>
          <surface>
            <contact>
              <ode/>
            </contact>
            <bounce/>
            <friction>
              <torsional>
                <ode/>
              </torsional>
              <ode/>
            </friction>
          </surface>
        </collision>
        <visual name='shelf_chassi_visual'>
          <pose>0 0 0 0 -0 0</pose>
          <geometry>
            <mesh>
              <scale>0.2 0.3 0.3</scale>
              <uri>/home/dan/.ignition/fuel/fuel.gazebosim.org/ngd1004/models/shelf/1/meshes/shelf_big_movai.dae</uri>
            </mesh>
          </geometry>
        </visual>
        <self_collide>1</self_collide>
        <enable_wind>0</enable_wind>
        <kinematic>0</kinematic>
      </link>
      <static>1</static>
    </model>
    <model name='shelf_clone_3'>
      <pose>3.92911 3.50547 0 0 -0 0</pose>
      <self_collide>1</self_collide>
      <link name='shelf_base'>
        <pose>-0.5 0 0 0 -0 0</pose>
        <collision name='shelf_chassi_collision'>
          <pose>0 0 0.9 0 -0 0</pose>
          <geometry>
            <box>
              <size>3.6 0.6 1.8</size>
            </box>
          </geometry>
          <max_contacts>10</max_contacts>
          <surface>
            <contact>
              <ode/>
            </contact>
            <bounce/>
            <friction>
              <torsional>
                <ode/>
              </torsional>
              <ode/>
            </friction>
          </surface>
        </collision>
        <visual name='shelf_chassi_visual'>
          <pose>0 0 0 0 -0 0</pose>
          <geometry>
            <mesh>
              <scale>0.2 0.3 0.3</scale>
              <uri>/home/dan/.ignition/fuel/fuel.gazebosim.org/ngd1004/models/shelf/1/meshes/shelf_big_movai.dae</uri>
            </mesh>
          </geometry>
        </visual>
        <self_collide>1</self_collide>
        <enable_wind>0</enable_wind>
        <kinematic>0</kinematic>
      </link>
      <static>1</static>
    </model>
    <light name='user_spot_light_0' type='spot'>
      <pose>-1.88693 -0.966713 1 0 -0 0</pose>
      <diffuse>0.5 0.5 0.5 1</diffuse>
      <specular>0.1 0.1 0.1 1</specular>
      <direction>0 0 -1</direction>
      <attenuation>
        <range>20</range>
        <constant>0.5</constant>
        <linear>0.01</linear>
        <quadratic>0.001</quadratic>
      </attenuation>
      <cast_shadows>0</cast_shadows>
      <spot>
        <inner_angle>0.6</inner_angle>
        <outer_angle>1</outer_angle>
        <falloff>1</falloff>
      </spot>
    </light>
    <light name='user_spot_light_0_clone' type='spot'>
      <pose>0.430291 7.89344 10 0 -0 0</pose>
      <diffuse>0.498039 0.498039 0.498039 1</diffuse>
      <specular>0.0980392 0.0980392 0.0980392 1</specular>
      <direction>0 0 -1</direction>
      <attenuation>
        <range>20</range>
        <constant>0.5</constant>
        <linear>0.01</linear>
        <quadratic>0.001</quadratic>
      </attenuation>
      <cast_shadows>0</cast_shadows>
      <spot>
        <inner_angle>0.6</inner_angle>
        <outer_angle>1</outer_angle>
        <falloff>1</falloff>
      </spot>
    </light>
    <light name='user_spot_light_0_clone_0' type='spot'>
      <pose>-5.71325 4.28744 10 0 -0 0</pose>
      <diffuse>0.498039 0.498039 0.498039 1</diffuse>
      <specular>0.0980392 0.0980392 0.0980392 1</specular>
      <direction>0 0 -1</direction>
      <attenuation>
        <range>20</range>
        <constant>0.5</constant>
        <linear>0.01</linear>
        <quadratic>0.001</quadratic>
      </attenuation>
      <cast_shadows>0</cast_shadows>
      <spot>
        <inner_angle>0.6</inner_angle>
        <outer_angle>1</outer_angle>
        <falloff>1</falloff>
      </spot>
    </light>
    <light name='user_spot_light_0_clone_1' type='spot'>
      <pose>6.11006 4.8761 10 0 -0 0</pose>
      <diffuse>0.498039 0.498039 0.498039 1</diffuse>
      <specular>0.0980392 0.0980392 0.0980392 1</specular>
      <direction>0 0 -1</direction>
      <attenuation>
        <range>20</range>
        <constant>0.5</constant>
        <linear>0.01</linear>
        <quadratic>0.001</quadratic>
      </attenuation>
      <cast_shadows>0</cast_shadows>
      <spot>
        <inner_angle>0.6</inner_angle>
        <outer_angle>1</outer_angle>
        <falloff>1</falloff>
      </spot>
    </light>
    <light name='user_spot_light_0_clone_2' type='spot'>
      <pose>-5.69627 5.14657 10 0 -0 0</pose>
      <diffuse>0.498039 0.498039 0.498039 1</diffuse>
      <specular>0.0980392 0.0980392 0.0980392 1</specular>
      <direction>0 0 -1</direction>
      <attenuation>
        <range>20</range>
        <constant>0.5</constant>
        <linear>0.01</linear>
        <quadratic>0.001</quadratic>
      </attenuation>
      <cast_shadows>0</cast_shadows>
      <spot>
        <inner_angle>0.6</inner_angle>
        <outer_angle>1</outer_angle>
        <falloff>1</falloff>
      </spot>
    </light>
    <gui fullscreen='0'>
      <camera name='user_camera'>
        <pose>0.096345 -14.7946 7.60159 0 0.311643 1.55619</pose>
        <view_controller>orbit</view_controller>
        <projection_type>perspective</projection_type>
      </camera>
    </gui>
  </world>
</sdf>
